Workbook

Sheet Settings
B2: Settings Summary | E2: Chart of Accounts
E4: CATEGORY TYPE | F4: CATEGORY NAME | H4: INSTRUCTIONS
E5: Trading Income | F5: Sales Revenue
B6: BUSINESS NAME | C6: Alham Wear | E6: Trading Income | F6: Refunds to Customers | I6: - Enter your Business Name
E7: Trading Income | I7: - Choose your preferred Report Name
B8: REPORT NAME | C8: Income Statement | E8: Cost of Sales | F8: Purchases | I8: - Enter the Start Date and End Date in the format dd-mm-yyyy
E9: Cost of Sales | F9: Returns to Suppliers | I9: - Enter up to 3 Category Names for Trading Income
B10: START DATE | C10: 45108 | E10: Cost of Sales | I10: - Enter up to 3 Category Names for Cost of Sales
B11: END DATE | C11: 45473 | E11: Expenses | F11: Advertising and Marketing | I11: - Enter up to 25 Category Names for Expenses
E12: Expenses | F12: Bank Fees | I12: - Enter up to 3 Category Names for Other Income
E13: Expenses | F13: Business Meals | I13: - Enter up to 2 Category Names for Taxed Paid
E14: Expenses | F14: Client Entertainment | I14: - Enter up to 5 Category Names for Capital Purchases
E15: Expenses | F15: Computers Expenses
E16: Expenses | F16: Motor Vehicle Expenses
E17: Expenses | F17: Contractors
E18: Expenses | F18: Insurance Fees
E19: Expenses | F19: Interest Paid
E20: Expenses | F20: Professional Fees
E21: Expenses | F21: Licenses or Fees
E22: Expenses | F22: Miscellaneous Expenses
E23: Expenses | F23: Telephone and Internet
E24: Expenses | F24: Electricity and Gas
E25: Expenses | F25: Postage and Shipping
E26: Expenses | F26: Rent or Lease
... E30: Expenses | F30: Mehtab Personal Expenses
E31: Expenses
E32: Expenses
E33: Expenses
E34: Expenses
E35: Expenses
E36: Other Income | F36: Interest Income
E37: Other Income | F37: Other Income
E38: Other Income
E39: Taxes Paid | F39: Tax Paid
E40: Taxes Paid
E41: Capital Purchases | F41: Motor Vehicles
E42: Capital Purchases | F42: Computer Hardware
E43: Capital Purchases | F43: Furniture
E44: Capital Purchases
E45: Capital Purchases

Sheet Bookkeeping
B2: Transactions | I2: =IF(COUNTIF($G$6:$G$1006,"ERROR")>0,"Amount has no Category Name","")
B3: =IF(COUNTIF($C$6:$C$1006,"ERROR")>0,"Date Out of Range","") | I3: =IF(COUNTIF($J$6:$J$1006,"ERROR")>0,"Category Name Mismatch","")
B4: DATE | E4: DESCRIPTION | F4: AMOUNT | I4: CATEGORY NAME | Q4: INSTRUCTIONS
B6: 45199 | C6: =IF(B6="","",IF(AND($B6>=Settings!$C$10,$B6<=Settings!$C$11),"OK","ERROR")) -> OK | E6: Sale | F6: 45000 | G6: =IF(F6="","",IF(I6<>"","OK","ERROR")) -> OK | I6: Sales Revenue | J6: =IF(I6="","",IF(ISERROR($K6)=TRUE,"ERROR","OK")) -> OK | K6: =IF(I6="","",MATCH($I6,Settings!$F$5:$F$46,0)) -> 1 | O6: {=_xlfn._xlws.FILTER(Settings!F5:F45,(Settings!F5:F45<>""))} -> Sales Revenue
B7: 45200 | C7: =IF(B7="","",IF(AND($B7>=Settings!$C$10,$B7<=Settings!$C$11),"OK","ERROR")) -> OK | E7: Inventory | F7: 9500 | G7: =IF(F7="","",IF(I7<>"","OK","ERROR")) -> OK | I7: Purchases | J7: =IF(I7="","",IF(ISERROR($K7)=TRUE,"ERROR","OK")) -> OK | K7: =IF(I7="","",MATCH($I7,Settings!$F$5:$F$46,0)) -> 4 | O7: Refunds to Customers | R7: Enter up to 1,000 transactions. For each transaction:
B8: 45201 | C8: =IF(B8="","",IF(AND($B8>=Settings!$C$10,$B8<=Settings!$C$11),"OK","ERROR")) -> OK | E8: Customer refund | F8: 50 | G8: =IF(F8="","",IF(I8<>"","OK","ERROR")) -> OK | I8: Refunds to Customers | J8: =IF(I8="","",IF(ISERROR($K8)=TRUE,"ERROR","OK")) -> OK | K8: =IF(I8="","",MATCH($I8,Settings!$F$5:$F$46,0)) -> 2 | O8: Purchases | S8: - The Date must be within the date range on the Settings tab
B9: 45202 | C9: =IF(B9="","",IF(AND($B9>=Settings!$C$10,$B9<=Settings!$C$11),"OK","ERROR")) -> OK | E9: Bank interest received | F9: 25 | G9: =IF(F9="","",IF(I9<>"","OK","ERROR")) -> OK | I9: Interest Income | J9: =IF(I9="","",IF(ISERROR($K9)=TRUE,"ERROR","OK")) -> OK | K9: =IF(I9="","",MATCH($I9,Settings!$F$5:$F$46,0)) -> 32 | O9: Returns to Suppliers | S9: - The Description can be anything you like
B10: 45203 | C10: =IF(B10="","",IF(AND($B10>=Settings!$C$10,$B10<=Settings!$C$11),"OK","ERROR")) -> OK | E10: Electricity bill | F10: 78 | G10: =IF(F10="","",IF(I10<>"","OK","ERROR")) -> OK | I10: Electricity and Gas | J10: =IF(I10="","",IF(ISERROR($K10)=TRUE,"ERROR","OK")) -> OK | K10: =IF(I10="","",MATCH($I10,Settings!$F$5:$F$46,0)) -> 20 | O10: Advertising and Marketing | S10: - All Amounts must be positive numbers (no negatives)
B11: 45204 | C11: =IF(B11="","",IF(AND($B11>=Settings!$C$10,$B11<=Settings!$C$11),"OK","ERROR")) -> OK | E11: Income tax paid | F11: 870 | G11: =IF(F11="","",IF(I11<>"","OK","ERROR")) -> OK | I11: Tax Paid | J11: =IF(I11="","",IF(ISERROR($K11)=TRUE,"ERROR","OK")) -> OK | K11: =IF(I11="","",MATCH($I11,Settings!$F$5:$F$46,0)) -> 35 | O11: Bank Fees | S11: - Choose a Category Name from the Chart of Accounts
B12: 45205 | C12: =IF(B12="","",IF(AND($B12>=Settings!$C$10,$B12<=Settings!$C$11),"OK","ERROR")) -> OK | E12: Purchases | F12: 4500 | G12: =IF(F12="","",IF(I12<>"","OK","ERROR")) -> OK | I12: Furniture | J12: =IF(I12="","",IF(ISERROR($K12)=TRUE,"ERROR","OK")) -> OK | K12: =IF(I12="","",MATCH($I12,Settings!$F$5:$F$46,0)) -> 39 | O12: Business Meals
B13: 45206 | C13: =IF(B13="","",IF(AND($B13>=Settings!$C$10,$B13<=Settings!$C$11),"OK","ERROR")) -> OK | E13: Revenue | F13: 7900 | G13: =IF(F13="","",IF(I13<>"","OK","ERROR")) -> OK | I13: Sales Revenue | J13: =IF(I13="","",IF(ISERROR($K13)=TRUE,"ERROR","OK")) -> OK | K13: =IF(I13="","",MATCH($I13,Settings!$F$5:$F$46,0)) -> 1 | O13: Client Entertainment | S13: ** Warning: if you change a Category Name in the Chart of Accounts
B14: 45207 | C14: =IF(B14="","",IF(AND($B14>=Settings!$C$10,$B14<=Settings!$C$11),"OK","ERROR")) -> OK | E14: Purchased stock | F14: 25 | G14: =IF(F14="","",IF(I14<>"","OK","ERROR")) -> OK | I14: Purchases | J14: =IF(I14="","",IF(ISERROR($K14)=TRUE,"ERROR","OK")) -> OK | K14: =IF(I14="","",MATCH($I14,Settings!$F$5:$F$46,0)) -> 4 | O14: Computers Expenses | S14: you'll need to update your Category Name selections here!
B15: 45208 | C15: =IF(B15="","",IF(AND($B15>=Settings!$C$10,$B15<=Settings!$C$11),"OK","ERROR")) -> OK | E15: Stock returned to supplier | F15: 30 | G15: =IF(F15="","",IF(I15<>"","OK","ERROR")) -> OK | I15: Returns to Suppliers | J15: =IF(I15="","",IF(ISERROR($K15)=TRUE,"ERROR","OK")) -> OK | K15: =IF(I15="","",MATCH($I15,Settings!$F$5:$F$46,0)) -> 5 | O15: Motor Vehicle Expenses
B16: 45209 | C16: =IF(B16="","",IF(AND($B16>=Settings!$C$10,$B16<=Settings!$C$11),"OK","ERROR")) -> OK | E16: Google marketing bill | F16: 100 | G16: =IF(F16="","",IF(I16<>"","OK","ERROR")) -> OK | I16: Advertising and Marketing | J16: =IF(I16="","",IF(ISERROR($K16)=TRUE,"ERROR","OK")) -> OK | K16: =IF(I16="","",MATCH($I16,Settings!$F$5:$F$46,0)) -> 7 | O16: Contractors
B17: 45210 | C17: =IF(B17="","",IF(AND($B17>=Settings!$C$10,$B17<=Settings!$C$11),"OK","ERROR")) -> OK | E17: Transaction fees | F17: 6 | G17: =IF(F17="","",IF(I17<>"","OK","ERROR")) -> OK | I17: Bank Fees | J17: =IF(I17="","",IF(ISERROR($K17)=TRUE,"ERROR","OK")) -> OK | K17: =IF(I17="","",MATCH($I17,Settings!$F$5:$F$46,0)) -> 8 | O17: Insurance Fees
B18: 45211 | C18: =IF(B18="","",IF(AND($B18>=Settings!$C$10,$B18<=Settings!$C$11),"OK","ERROR")) -> OK | E18: Meal | F18: 45 | G18: =IF(F18="","",IF(I18<>"","OK","ERROR")) -> OK | I18: Business Meals | J18: =IF(I18="","",IF(ISERROR($K18)=TRUE,"ERROR","OK")) -> OK | K18: =IF(I18="","",MATCH($I18,Settings!$F$5:$F$46,0)) -> 9 | O18: Interest Paid
B19: 45212 | C19: =IF(B19="","",IF(AND($B19>=Settings!$C$10,$B19<=Settings!$C$11),"OK","ERROR")) -> OK | E19: Meal with clients | F19: 40 | G19: =IF(F19="","",IF(I19<>"","OK","ERROR")) -> OK | I19: Client Entertainment | J19: =IF(I19="","",IF(ISERROR($K19)=TRUE,"ERROR","OK")) -> OK | K19: =IF(I19="","",MATCH($I19,Settings!$F$5:$F$46,0)) -> 10 | O19: Professional Fees
B20: 45213 | C20: =IF(B20="","",IF(AND($B20>=Settings!$C$10,$B20<=Settings!$C$11),"OK","ERROR")) -> OK | E20: Software license | F20: 150 | G20: =IF(F20="","",IF(I20<>"","OK","ERROR")) -> OK | I20: Computers Expenses | J20: =IF(I20="","",IF(ISERROR($K20)=TRUE,"ERROR","OK")) -> OK | K20: =IF(I20="","",MATCH($I20,Settings!$F$5:$F$46,0)) -> 11 | O20: Licenses or Fees
B21: 45214 | C21: =IF(B21="","",IF(AND($B21>=Settings!$C$10,$B21<=Settings!$C$11),"OK","ERROR")) -> OK | E21: Petrol for car | F21: 70 | G21: =IF(F21="","",IF(I21<>"","OK","ERROR")) -> OK | I21: Motor Vehicle Expenses | J21: =IF(I21="","",IF(ISERROR($K21)=TRUE,"ERROR","OK")) -> OK | K21: =IF(I21="","",MATCH($I21,Settings!$F$5:$F$46,0)) -> 12 | O21: Miscellaneous Expenses
B22: 45215 | C22: =IF(B22="","",IF(AND($B22>=Settings!$C$10,$B22<=Settings!$C$11),"OK","ERROR")) -> OK | E22: J. Jones contractor payment | F22: 500 | G22: =IF(F22="","",IF(I22<>"","OK","ERROR")) -> OK | I22: Contractors | J22: =IF(I22="","",IF(ISERROR($K22)=TRUE,"ERROR","OK")) -> OK | K22: =IF(I22="","",MATCH($I22,Settings!$F$5:$F$46,0)) -> 13 | O22: Telephone and Internet
B23: 45216 | C23: =IF(B23="","",IF(AND($B23>=Settings!$C$10,$B23<=Settings!$C$11),"OK","ERROR")) -> OK | E23: PI insurance premium | F23: 1000 | G23: =IF(F23="","",IF(I23<>"","OK","ERROR")) -> OK | I23: Insurance Fees | J23: =IF(I23="","",IF(ISERROR($K23)=TRUE,"ERROR","OK")) -> OK | K23: =IF(I23="","",MATCH($I23,Settings!$F$5:$F$46,0)) -> 14 | O23: Electricity and Gas
B24: 45217 | C24: =IF(B24="","",IF(AND($B24>=Settings!$C$10,$B24<=Settings!$C$11),"OK","ERROR")) -> OK | E24: Bank interest paid | F24: 13 | G24: =IF(F24="","",IF(I24<>"","OK","ERROR")) -> OK | I24: Interest Paid | J24: =IF(I24="","",IF(ISERROR($K24)=TRUE,"ERROR","OK")) -> OK | K24: =IF(I24="","",MATCH($I24,Settings!$F$5:$F$46,0)) -> 15 | O24: Postage and Shipping
B25: 45218 | C25: =IF(B25="","",IF(AND($B25>=Settings!$C$10,$B25<=Settings!$C$11),"OK","ERROR")) -> OK | E25: Accountant fee | F25: 1400 | G25: =IF(F25="","",IF(I25<>"","OK","ERROR")) -> OK | I25: Professional Fees | J25: =IF(I25="","",IF(ISERROR($K25)=TRUE,"ERROR","OK")) -> OK | K25: =IF(I25="","",MATCH($I25,Settings!$F$5:$F$46,0)) -> 16 | O25: Rent or Lease
B26: 45219 | C26: =IF(B26="","",IF(AND($B26>=Settings!$C$10,$B26<=Settings!$C$11),"OK","ERROR")) -> OK | E26: Business name license | F26: 80 | G26: =IF(F26="","",IF(I26<>"","OK","ERROR")) -> OK | I26: Licenses or Fees | J26: =IF(I26="","",IF(ISERROR($K26)=TRUE,"ERROR","OK")) -> OK | K26: =IF(I26="","",MATCH($I26,Settings!$F$5:$F$46,0)) -> 17 | O26: Software Expenses
... B34: 45227 | C34: =IF(B34="","",IF(AND($B34>=Settings!$C$10,$B34<=Settings!$C$11),"OK","ERROR")) -> OK | E34: Train ticket to conference | F34: 23 | G34: =IF(F34="","",IF(I34<>"","OK","ERROR")) -> OK | I34: Travel and Transportation | J34: =IF(I34="","",IF(ISERROR($K34)=TRUE,"ERROR","OK")) -> OK | K34: =IF(I34="","",MATCH($I34,Settings!$F$5:$F$46,0)) -> 25 | O34: Computer Hardware
B35: 45228 | C35: =IF(B35="","",IF(AND($B35>=Settings!$C$10,$B35<=Settings!$C$11),"OK","ERROR")) -> OK | E35: Income tax paid | F35: 1500 | G35: =IF(F35="","",IF(I35<>"","OK","ERROR")) -> OK | I35: Tax Paid | J35: =IF(I35="","",IF(ISERROR($K35)=TRUE,"ERROR","OK")) -> OK | K35: =IF(I35="","",MATCH($I35,Settings!$F$5:$F$46,0)) -> 35
B36: 45229 | C36: =IF(B36="","",IF(AND($B36>=Settings!$C$10,$B36<=Settings!$C$11),"OK","ERROR")) -> OK | E36: Meal Expense oct-23 | F36: 1200 | G36: =IF(F36="","",IF(I36<>"","OK","ERROR")) -> OK | I36: Miscellaneous Expenses | J36: =IF(I36="","",IF(ISERROR($K36)=TRUE,"ERROR","OK")) -> OK | K36: =IF(I36="","",MATCH($I36,Settings!$F$5:$F$46,0)) -> 18
B37: 45229 | C37: =IF(B37="","",IF(AND($B37>=Settings!$C$10,$B37<=Settings!$C$11),"OK","ERROR")) -> OK | E37: Manager Expenses OCT-23 | F37: 75000 | G37: =IF(F37="","",IF(I37<>"","OK","ERROR")) -> OK | I37: Mehtab Personal Expenses | J37: =IF(I37="","",IF(ISERROR($K37)=TRUE,"ERROR","OK")) -> OK | K37: =IF(I37="","",MATCH($I37,Settings!$F$5:$F$46,0)) -> 26
B38: 45229 | C38: =IF(B38="","",IF(AND($B38>=Settings!$C$10,$B38<=Settings!$C$11),"OK","ERROR")) -> OK | E38: Sales to Mr. ABC | F38: 175000 | G38: =IF(F38="","",IF(I38<>"","OK","ERROR")) -> OK | I38: Sales Revenue | J38: =IF(I38="","",IF(ISERROR($K38)=TRUE,"ERROR","OK")) -> OK | K38: =IF(I38="","",MATCH($I38,Settings!$F$5:$F$46,0)) -> 1
B39: 45229 | C39: =IF(B39="","",IF(AND($B39>=Settings!$C$10,$B39<=Settings!$C$11),"OK","ERROR")) -> OK | E39: Sales to Mr. ABC | G39: =IF(F39="","",IF(I39<>"","OK","ERROR")) | I39: Sales Revenue | J39: =IF(I39="","",IF(ISERROR($K39)=TRUE,"ERROR","OK")) -> OK | K39: =IF(I39="","",MATCH($I39,Settings!$F$5:$F$46,0)) -> 1
C40: =IF(B40="","",IF(AND($B40>=Settings!$C$10,$B40<=Settings!$C$11),"OK","ERROR")) | E40: Sales to Mr. ABC | G40: =IF(F40="","",IF(I40<>"","OK","ERROR")) | J40: =IF(I40="","",IF(ISERROR($K40)=TRUE,"ERROR","OK")) | K40: =IF(I40="","",MATCH($I40,Settings!$F$5:$F$46,0))
C41: =IF(B41="","",IF(AND($B41>=Settings!$C$10,$B41<=Settings!$C$11),"OK","ERROR")) | G41: =IF(F41="","",IF(I41<>"","OK","ERROR")) | J41: =IF(I41="","",IF(ISERROR($K41)=TRUE,"ERROR","OK")) | K41: =IF(I41="","",MATCH($I41,Settings!$F$5:$F$46,0))
C42: =IF(B42="","",IF(AND($B42>=Settings!$C$10,$B42<=Settings!$C$11),"OK","ERROR")) | G42: =IF(F42="","",IF(I42<>"","OK","ERROR")) | J42: =IF(I42="","",IF(ISERROR($K42)=TRUE,"ERROR","OK")) | K42: =IF(I42="","",MATCH($I42,Settings!$F$5:$F$46,0))
C43: =IF(B43="","",IF(AND($B43>=Settings!$C$10,$B43<=Settings!$C$11),"OK","ERROR")) | G43: =IF(F43="","",IF(I43<>"","OK","ERROR")) | J43: =IF(I43="","",IF(ISERROR($K43)=TRUE,"ERROR","OK")) | K43: =IF(I43="","",MATCH($I43,Settings!$F$5:$F$46,0))
C44: =IF(B44="","",IF(AND($B44>=Settings!$C$10,$B44<=Settings!$C$11),"OK","ERROR")) | G44: =IF(F44="","",IF(I44<>"","OK","ERROR")) | J44: =IF(I44="","",IF(ISERROR($K44)=TRUE,"ERROR","OK")) | K44: =IF(I44="","",MATCH($I44,Settings!$F$5:$F$46,0))
C45: =IF(B45="","",IF(AND($B45>=Settings!$C$10,$B45<=Settings!$C$11),"OK","ERROR")) | G45: =IF(F45="","",IF(I45<>"","OK","ERROR")) | J45: =IF(I45="","",IF(ISERROR($K45)=TRUE,"ERROR","OK")) | K45: =IF(I45="","",MATCH($I45,Settings!$F$5:$F$46,0))
C46: =IF(B46="","",IF(AND($B46>=Settings!$C$10,$B46<=Settings!$C$11),"OK","ERROR")) | G46: =IF(F46="","",IF(I46<>"","OK","ERROR")) | J46: =IF(I46="","",IF(ISERROR($K46)=TRUE,"ERROR","OK")) | K46: =IF(I46="","",MATCH($I46,Settings!$F$5:$F$46,0))
C47: =IF(B47="","",IF(AND($B47>=Settings!$C$10,$B47<=Settings!$C$11),"OK","ERROR")) | G47: =IF(F47="","",IF(I47<>"","OK","ERROR")) | J47: =IF(I47="","",IF(ISERROR($K47)=TRUE,"ERROR","OK")) | K47: =IF(I47="","",MATCH($I47,Settings!$F$5:$F$46,0))
C48: =IF(B48="","",IF(AND($B48>=Settings!$C$10,$B48<=Settings!$C$11),"OK","ERROR")) | G48: =IF(F48="","",IF(I48<>"","OK","ERROR")) | J48: =IF(I48="","",IF(ISERROR($K48)=TRUE,"ERROR","OK")) | K48: =IF(I48="","",MATCH($I48,Settings!$F$5:$F$46,0))
C49: =IF(B49="","",IF(AND($B49>=Settings!$C$10,$B49<=Settings!$C$11),"OK","ERROR")) | G49: =IF(F49="","",IF(I49<>"","OK","ERROR")) | J49: =IF(I49="","",IF(ISERROR($K49)=TRUE,"ERROR","OK")) | K49: =IF(I49="","",MATCH($I49,Settings!$F$5:$F$46,0))
...

Sheet Summary Reports
B2: =Settings!$C$8 -> Income Statement | F2: Capital Purchases
C3: Alham Wear | G3: Alham Wear
B4: =TEXT(Settings!$C$10,"dd-mmm-yyyy")&" to "&TEXT(Settings!$C$11,"dd-mmm-yyyy") -> 01-Jul-2023 to 30-Jun-2024 | F4: =TEXT(Settings!$C$10,"dd-mmm-yyyy")&" to "&TEXT(Settings!$C$11,"dd-mmm-yyyy") -> 01-Jul-2023 to 30-Jun-2024
B6: Trading Income | F6: Fixed Asset Category
C7: =IF(Settings!F5<>"",Settings!F5,"") -> Sales Revenue | D7: =IFERROR(SUMIF(Bookkeeping!$I$5:$I$1006,'Summary Reports'!$C7,Bookkeeping!$F$5:$F$1006),0) -> 227900 | G7: =Settings!F41 -> Motor Vehicles | H7: =IFERROR(SUMIF(Bookkeeping!$I$5:$I$1006,'Summary Reports'!$G7,Bookkeeping!$F$5:$F$1006),0) -> 0
C8: =IF(Settings!F6<>"",Settings!F6,"") -> Refunds to Customers | D8: =-IFERROR(SUMIF(Bookkeeping!$I$5:$I$1006,'Summary Reports'!$C8,Bookkeeping!$F$5:$F$1006),0) -> -50 | G8: =Settings!F42 -> Computer Hardware | H8: =IFERROR(SUMIF(Bookkeeping!$I$5:$I$1006,'Summary Reports'!$G8,Bookkeeping!$F$5:$F$1006),0) -> 0
C9: =IF(Settings!F7<>"",Settings!F7,"") | D9: =IFERROR(SUMIF(Bookkeeping!$I$5:$I$1006,'Summary Reports'!$C9,Bookkeeping!$F$5:$F$1006),0) -> 0 | G9: =Settings!F43 -> Furniture | H9: =IFERROR(SUMIF(Bookkeeping!$I$5:$I$1006,'Summary Reports'!$G9,Bookkeeping!$F$5:$F$1006),0) -> 4500
D10: =SUM(D7:D9) -> 227850 | G10: =IF(Settings!F44<>"",Settings!F44,"") | H10: =IFERROR(SUMIF(Bookkeeping!$I$5:$I$1006,'Summary Reports'!$G10,Bookkeeping!$F$5:$F$1006),0) -> 0
B11: Cost of Sales | G11: =IF(Settings!F45<>"",Settings!F45,"") | H11: =IFERROR(SUMIF(Bookkeeping!$I$5:$I$1006,'Summary Reports'!$G11,Bookkeeping!$F$5:$F$1006),0) -> 0
C12: =IF(Settings!F8<>"",Settings!F8,"") -> Purchases | D12: =IFERROR(SUMIF(Bookkeeping!$I$5:$I$1006,'Summary Reports'!$C12,Bookkeeping!$F$5:$F$1006),0) -> 9525 | F12: TOTAL CAPITAL PURCHASES | H12: =SUM(H7:H11) -> 4500
C13: =IF(Settings!F9<>"",Settings!F9,"") -> Returns to Suppliers | D13: =-IFERROR(SUMIF(Bookkeeping!$I$5:$I$1006,'Summary Reports'!$C13,Bookkeeping!$F$5:$F$1006),0) -> -30
C14: =IF(Settings!F10<>"",Settings!F10,"") | D14: =IFERROR(SUMIF(Bookkeeping!$I$5:$I$1006,'Summary Reports'!$C14,Bookkeeping!$F$5:$F$1006),0) -> 0
D15: =SUM(D12:D14) -> 9495
B16: GROSS PROFIT/(LOSS) | D16: =D10-D15 -> 218355
B18: Expenses
C19: =IF(Settings!F11<>"",Settings!F11,"") -> Advertising and Marketing | D19: =IFERROR(SUMIF(Bookkeeping!$I$5:$I$1006,'Summary Reports'!$C19,Bookkeeping!$F$5:$F$1006),0) -> 100
C20: =IF(Settings!F12<>"",Settings!F12,"") -> Bank Fees | D20: =IFERROR(SUMIF(Bookkeeping!$I$5:$I$1006,'Summary Reports'!$C20,Bookkeeping!$F$5:$F$1006),0) -> 6
C21: =IF(Settings!F13<>"",Settings!F13,"") -> Business Meals | D21: =IFERROR(SUMIF(Bookkeeping!$I$5:$I$1006,'Summary Reports'!$C21,Bookkeeping!$F$5:$F$1006),0) -> 45
C22: =IF(Settings!F14<>"",Settings!F14,"") -> Client Entertainment | D22: =IFERROR(SUMIF(Bookkeeping!$I$5:$I$1006,'Summary Reports'!$C22,Bookkeeping!$F$5:$F$1006),0) -> 40
C23: =IF(Settings!F15<>"",Settings!F15,"") -> Computers Expenses | D23: =IFERROR(SUMIF(Bookkeeping!$I$5:$I$1006,'Summary Reports'!$C23,Bookkeeping!$F$5:$F$1006),0) -> 150
C24: =IF(Settings!F16<>"",Settings!F16,"") -> Motor Vehicle Expenses | D24: =IFERROR(SUMIF(Bookkeeping!$I$5:$I$1006,'Summary Reports'!$C24,Bookkeeping!$F$5:$F$1006),0) -> 70
C25: =IF(Settings!F17<>"",Settings!F17,"") -> Contractors | D25: =IFERROR(SUMIF(Bookkeeping!$I$5:$I$1006,'Summary Reports'!$C25,Bookkeeping!$F$5:$F$1006),0) -> 500
C26: =IF(Settings!F18<>"",Settings!F18,"") -> Insurance Fees | D26: =IFERROR(SUMIF(Bookkeeping!$I$5:$I$1006,'Summary Reports'!$C26,Bookkeeping!$F$5:$F$1006),0) -> 1000
C27: =IF(Settings!F19<>"",Settings!F19,"") -> Interest Paid | D27: =IFERROR(SUMIF(Bookkeeping!$I$5:$I$1006,'Summary Reports'!$C27,Bookkeeping!$F$5:$F$1006),0) -> 13
C28: =IF(Settings!F20<>"",Settings!F20,"") -> Professional Fees | D28: =IFERROR(SUMIF(Bookkeeping!$I$5:$I$1006,'Summary Reports'!$C28,Bookkeeping!$F$5:$F$1006),0) -> 1400
C29: =IF(Settings!F21<>"",Settings!F21,"") -> Licenses or Fees | D29: =IFERROR(SUMIF(Bookkeeping!$I$5:$I$1006,'Summary Reports'!$C29,Bookkeeping!$F$5:$F$1006),0) -> 80
C30: =IF(Settings!F22<>"",Settings!F22,"") -> Miscellaneous Expenses | D30: =IFERROR(SUMIF(Bookkeeping!$I$5:$I$1006,'Summary Reports'!$C30,Bookkeeping!$F$5:$F$1006),0) -> 1350
... C43: =IF(Settings!F35<>"",Settings!F35,"") | D43: =IFERROR(SUMIF(Bookkeeping!$I$5:$I$1006,'Summary Reports'!$C43,Bookkeeping!$F$5:$F$1006),0) -> 0
D44: =SUM(D19:D43) -> 85674
B45: OPERATING PROFIT/(LOSS) | D45: =D16-D44 -> 132681
B47: Other Income
C48: =IF(Settings!F36<>"",Settings!F36,"") -> Interest Income | D48: =IFERROR(SUMIF(Bookkeeping!$I$5:$I$1006,'Summary Reports'!$C48,Bookkeeping!$F$5:$F$1006),0) -> 25
C49: =IF(Settings!F37<>"",Settings!F37,"") -> Other Income | D49: =IFERROR(SUMIF(Bookkeeping!$I$5:$I$1006,'Summary Reports'!$C49,Bookkeeping!$F$5:$F$1006),0) -> 0
C50: =IF(Settings!F38<>"",Settings!F38,"") | D50: =IFERROR(SUMIF(Bookkeeping!$I$5:$I$1006,'Summary Reports'!$C50,Bookkeeping!$F$5:$F$1006),0) -> 0
D51: =SUM(D48:D50) -> 25
B52: PROFIT/(LOSS) BEFORE TAX | D52: =D45+D51 -> 132706
B54: Taxes Paid
C55: =IF(Settings!F39<>"",Settings!F39,"") -> Tax Paid | D55: =IFERROR(SUMIF(Bookkeeping!$I$5:$I$1006,'Summary Reports'!$C55,Bookkeeping!$F$5:$F$1006),0) -> 2370
C56: =IF(Settings!F40<>"",Settings!F40,"") | D56: =IFERROR(SUMIF(Bookkeeping!$I$5:$I$1006,'Summary Reports'!$C56,Bookkeeping!$F$5:$F$1006),0) -> 0
D57: =SUM(D55:D56) -> 2370
...

Sheet Sheet1
